Workbook

Sheet Tanker PDA
A1: Proforma Disbursement Account (PDA)
A6: Addressing To: | C6: Vitol International Shipping Pte Ltd | H6: Port: Batumi, Georgia | L6: Dated: | M6: 45905
A7: Cargo Details
A8: Description | E8: Estimated Qty. | I8: Activity GLP17718961
A9: LPG | E9: 4800 MT | I9: Loading
A10: Parameters of the Tanker ship
A11: Name | D11: IMO | E11: GRT | H11: Reduced GRT | J11: LOA | K11: Beam | L11: Depth | M11: L x B x D
A12: BELGRAVIA V | D12: 9341897 | E12: 10000 | H12: 8000 | J12: 119.95 | K12: 19.02 | L12: 10 | M12: =L12*K12*J12 -> 22814.49
A13: Services
A14: Service Group | D14: Service Description | I14: Calculation Method | L14: Amount (USD)
A15: A: Port Expenses | D15: Tonnage dues | I15: 1.15$ 1.30$ | J15: < 10000 GRT > 10000 GRT | L15: =H12*1.15 -> 9200
D16: Berth dues | I16: 0.15$ | J16: GRT: | L16: =H12*0.15 -> 1200
D17: Towage - Inwards | I17: 0.32$ | J17: GRT: | L17: =H12*0.32 -> 2560
D18: Towage - Outwards | I18: 0.32$ | J18: GRT: | L18: =H12*0.32 -> 2560
D19: Mooring Expenses - Mooring | I19: Fixed fee: +25 Holiday | L19: 250
D20: Mooring Expenses - Unmooring | I20: Fixed fee: +25 Holiday | L20: 250
D21: Sanitary dues | I21: 0.10$ | J21: GRT | L21: =H12*0.1 -> 800
D22: Watchman service dues | I22: 0.07$ | J22: GRT | L22: =H12*0.07 -> 560
D23: Fire prevention dues | I23: 10$ | J23: Hour | L23: 1500
D24: Launch boat | I24: 60.00$ | J24: Per trip CBM(6 trip) Per trip Anchorage | L24: 0
D25: Daily ship positions | I25: 0.07$ 0.08$ | J25: < 10000 GRT > 10000 GRT | L25: =H12*0.07 -> 560
A26: B: Pilot Expenses | D26: Pilotage -Inwards Night time 22:00-06:30 + 25% | I26: 0.030$ | J26: L x B x D | L26: =(M12*0.03)+(M12*0.03)*0.25 -> 855.54337
D27: Pilotage -Outwards Night time 22:00-06:30 + 25% | I27: 0.030$ | J27: L x B x D | L27: =(M12*0.03)+(M12*0.03)*0.25 -> 855.54337
A28: C: Maritime Transport Agency | D28: Environment pollution dues | I28: www.mta.gov.ge | L28: =1130.56/2.68 -> 421.85075
D29: Harbour dues | I29: www.mta.gov.ge | L29: =1276/2.68 -> 476.1194
D30: Georep dues | I30: GEL 350 | L30: =580/2.68 -> 216.41791
D31: Monitoring service (VTS) | I31: 0.16$ x reduced | L31: =H12*0.16/2.68 -> 477.61194
A32: D: Hydrography | D32: Light dues SBT YES | I32: 0.09$ x gross | L32: =E12*0.09 -> 900
A33: E: Agency Fees | D33: Agency Fee | I33: Lumpsum all inclusive | L33: 1801.74
K34: SUBTOTAL (USD) | L34: =SUM(L15:M33) -> 25444.827
A36: NOTE: Please transfer 100% of PDA amount, due to port, authorities and service provider requirements, all costs to be paid before vessel arrival.
A37: - Fresh Water at port area USD 6.00$ PMT + USD 400.00$ Barge shifting
A38: - Launch hire USD 60.00 per trip to CBM, USD 90.00 per hour for trips to Anchorage
A39: - Calculation method and basis for dimensions provided above, Final Disbursement account will be corrected as per actual
A40: - At Georgian ports, additional payment (+25%) for Pilotage, Mooring, Tugboats are imposed during National holidays;
A42: Account With Institution: BANK OF GEORGIA, SWIFT: BAGAGE22; 29a Gagarin street, Tbilisi 0160, Georgia
A43: Intermediary bank: CITIBANK N.A., NEW-YORK, USA; SWIFT: CITIUS33,
A44: Beneficiary's name: Trans Logistic Batumi LLC (ID.: 405 660 413)
A45: Account: GE80BG0000000582360695
A48: Trans Logistic Batumi LLC (ID.: 405 660 413) Adr.: Office: 5, Chonkadze street, 6000, Batumi, Georgia
...

Sheet Tanker FDA
A1: Final Disbursement Account # 2025-045 Dated: 17.06.2025
A3: Addressing To: | C3: ='Tanker PDA'!C6:G6 -> Vitol International Shipping Pte Ltd
A5: Voyage details
A6: Arrival: 11-JUNE-2025 | D6: Departure: 16-JUNE-2025 | I6: Activity: LOADING GLP17102449
A8: Parameters of the Tanker ship
A9: Name | D9: IMO | E9: GRT | H9: Reduced GRT | J9: LOA | K9: Beam | L9: Depth | M9: L x B x D
A10: ='Tanker PDA'!A12:C12 -> BELGRAVIA V | D10: ='Tanker PDA'!D12 -> 9341897 | E10: ='Tanker PDA'!E12:G12 -> 10000 | H10: ='Tanker PDA'!H12:I12 -> 8000 | J10: ='Tanker PDA'!J12 -> 119.95 | K10: ='Tanker PDA'!K12 -> 19.02 | L10: ='Tanker PDA'!L12 -> 10 | M10: =L10*K10*J10 -> 22814.49
A11: `
A12: Service Group | D12: Service Description | I12: Calculation Method | L12: Amount (USD)
A14: A: Port Expenses | D14: Tonnage dues | I14: 1.15$ 1.30$ | J14: < 10000 GRT > 10000 GRT | M14: 8300.7
D15: Berth dues | I15: 0.15$ | J15: GRT | M15: 1082.7
A16: PORT INVOICE | D16: Towage - Inwards | I16: 0.32$ | J16: GRT | M16: 2309.76
A17: NO. BSP00362 | D17: Towage - Outwards | I17: 0.32$ | J17: GRT | K17: +25% Holiday fee | M17: 2309.76
A18: DATE: 17.06.2025 | D18: Mooring Expenses - Mooring | I18: Fixed fee | M18: 250
D19: Mooring Expenses - Unmooring | I19: Fixed fee | K19: +25% Holiday fee | M19: 250
D20: Sanitary dues | I20: 0.1$ | J20: GRT | M20: 721.8
D21: Watchman service dues | I21: 0.07$ | J21: GRT | M21: 505.26
D22: Fresh water supply | I22: 150 | J22: tn | K22: USD 6 | M22: 900
D23: Fire watch dues | I23: 126.5 | J23: 10$ per hour of port stay | M23: 1265
D24: Day ship position | I24: 0.07$ 0.08$ | J24: < 10000 GRT > 10000 GRT | M24: =0.07*H10 -> 560
A25: B: Pilot Expenses | D25: Pilotage -Inwards | I25: 0.03$ | J25: LxBxD < 5000 = 10000 | M25: 683.72
A26: PILOT INVOICE № 312 | D26: Night Rate | I26: 0.25 | M26: 170.93
D27: Pilotage - Outwards | I27: 0.03$ | J27: LxBxD>5000,but<12000=12000 | M27: 683.72
D28: Certificates of Origin | I28: Propane/Butane | M28: 400
A29: C: Maritime Transport | D29: Environment pollution dues | I29: www.mta.gov.ge | M29: =1130.56/2.7306 -> 414.03355
A30: Agency Expenes | D30: Harbour dues | I30: www.mta.gov.ge | M30: =1276/2.7306 -> 467.29656
A31: B-872 | B31: B-870 | D31: Georep dues | I31: www.mta.gov.ge | M31: =580/2.7306 -> 212.40753
A32: B-871 | B32: B-873 | D32: Monitoring service (VTS) | I32: www.mta.gov.ge | M32: =1154.88/2.7306 -> 422.94001
A33: D: Hydrography | C33: INV. N.20/B | D33: Lighthouse service fee | I33: 0.09$ | J33: L x B x D | M33: 649.62
A34: F: Agency Fees | D34: Agency Fee | I34: Lumpsum | M34: 1799.47
K36: SUBTOTAL (USD) | M36: =SUM(M14:M35) -> 24359.118
I37: Advance Received (USD) | M37: 12400.92
I38: Balance to YOUR favor (USD) | M38: =M37-M36 -> -11958.198 | XFD38: =SUM(N38:XFC38) -> 0
A40: Account With Institution: BANK OF GEORGIA, SWIFT: BAGAGE22; 29a Gagarin street, Tbilisi 0160, Georgia
A41: Intermediary bank: CITIBANK N.A., NEW-YORK, USA; SWIFT: CITIUS33,
A42: Beneficiary's name: Trans Logistic Batumi LLC (ID.: 405 660 413)
A43: Account: GE80BG0000000582360695
A46: Trans Logistic Batumi LLC (ID.: 405 660 413) Adr.: Office: 5, Chonkadze street, 6000, Batumi, Georgia
A47: PIC/POC: | B47: Giorgi Darchia | Mobile: +995 593 40 19 69
B48: Jaba Tarimanashvili | Mobile: +995 599 69 22 11
...

Sheet Harbour
A2: საქართველოს ნავსადგურში გემის შესვლა-გასვლის გაფორმება:
A3: 100-1000 GT – 440 ლარი;
A4: 1001-5000 GT – 792 ლარი;
A5: 5001-15000 GT – 1276 ლარი;
A6: 15001< GT – 1634 ლარი.

Sheet REINSPECTION
A1: გემის განმეორებითი შემოწმება ნავსადგურის სახელმწიფო კონტროლის მიერ – კანონმდებლობით
A2: დადგენილ ვადაში – 1 855 ლარი;

Sheet ENVIRONMENT
C3: FROM | D3: TO | H3: FEE | K3: GRT | L3: FEE
B4: - | C4: 1001 | D4: 1100 | E4: 0.20384615 | F4: 1100 | G4: 225 | H4: =G4+(D4-F4)*E4 -> 225 | K4: 8000 | L4: =SUMIF(D4:D593,ROUNDUP(K4,-2),H4:H593) -> 1157.7778
C5: 1101 | D5: 1200 | E5: 0.20384615 | F5: 1100 | G5: 225 | H5: =G5+(D5-F5)*E5 -> 245.38462
C6: 1201 | D6: 1300 | E6: 0.20384615 | F6: 1100 | G6: 225 | H6: =G6+(D6-F6)*E6 -> 265.76923
C7: 1301 | D7: 1400 | E7: 0.20384615 | F7: 1100 | G7: 225 | H7: =G7+(D7-F7)*E7 -> 286.15385
C8: 1401 | D8: 1500 | E8: 0.20384615 | F8: 1100 | G8: 225 | H8: =G8+(D8-F8)*E8 -> 306.53846
C9: 1501 | D9: 1600 | E9: 0.20384615 | F9: 1100 | G9: 225 | H9: =G9+(D9-F9)*E9 -> 326.92308
C10: 1601 | D10: 1700 | E10: 0.20384615 | F10: 1100 | G10: 225 | H10: =G10+(D10-F10)*E10 -> 347.30769
C11: 1701 | D11: 1800 | E11: 0.20384615 | F11: 1100 | G11: 225 | H11: =G11+(D11-F11)*E11 -> 367.69231
C12: 1801 | D12: 1900 | E12: 0.20384615 | F12: 1100 | G12: 225 | H12: =G12+(D12-F12)*E12 -> 388.07692
C13: 1901 | D13: 2000 | E13: 0.20384615 | F13: 1100 | G13: 225 | H13: =G13+(D13-F13)*E13 -> 408.46154
C14: 2001 | D14: 2100 | E14: 0.20384615 | F14: 1100 | G14: 225 | H14: =G14+(D14-F14)*E14 -> 428.84615
C15: 2101 | D15: 2200 | E15: 0.20384615 | F15: 1100 | G15: 225 | H15: =G15+(D15-F15)*E15 -> 449.23077
C16: 2201 | D16: 2300 | E16: 0.20384615 | F16: 1100 | G16: 225 | H16: =G16+(D16-F16)*E16 -> 469.61538
... C42: 4801 | D42: 4900 | E42: 0.20384615 | F42: 1100 | G42: 225 | H42: =G42+(D42-F42)*E42 -> 999.61538
B43: - | C43: 4901 | D43: 5000 | E43: 0.20384615 | F43: 1100 | G43: 225 | H43: =G43+(D43-F43)*E43 -> 1020
B44: - | C44: 5001 | D44: 5100 | E44: 0.038888889 | F44: 5100 | G44: 1045 | H44: =G44+(D44-F44)*E44 -> 1045
C45: 5101 | D45: 5200 | E45: 0.038888889 | F45: 5100 | G45: 1045 | H45: =G45+(D45-F45)*E45 -> 1048.8889
C46: 5201 | D46: 5300 | E46: 0.038888889 | F46: 5100 | G46: 1045 | H46: =G46+(D46-F46)*E46 -> 1052.7778
C47: 5301 | D47: 5400 | E47: 0.038888889 | F47: 5100 | G47: 1045 | H47: =G47+(D47-F47)*E47 -> 1056.6667
C48: 5401 | D48: 5500 | E48: 0.038888889 | F48: 5100 | G48: 1045 | H48: =G48+(D48-F48)*E48 -> 1060.5556
C49: 5501 | D49: 5600 | E49: 0.038888889 | F49: 5100 | G49: 1045 | H49: =G49+(D49-F49)*E49 -> 1064.4444
C50: 5601 | D50: 5700 | E50: 0.038888889 | F50: 5100 | G50: 1045 | H50: =G50+(D50-F50)*E50 -> 1068.3333
C51: 5701 | D51: 5800 | E51: 0.038888889 | F51: 5100 | G51: 1045 | H51: =G51+(D51-F51)*E51 -> 1072.2222
C52: 5801 | D52: 5900 | E52: 0.038888889 | F52: 5100 | G52: 1045 | H52: =G52+(D52-F52)*E52 -> 1076.1111
C53: 5901 | D53: 6000 | E53: 0.038888889 | F53: 5100 | G53: 1045 | H53: =G53+(D53-F53)*E53 -> 1080
C54: 6001 | D54: 6100 | E54: 0.038888889 | F54: 5100 | G54: 1045 | H54: =G54+(D54-F54)*E54 -> 1083.8889
C55: 6101 | D55: 6200 | E55: 0.038888889 | F55: 5100 | G55: 1045 | H55: =G55+(D55-F55)*E55 -> 1087.7778
C56: 6201 | D56: 6300 | E56: 0.038888889 | F56: 5100 | G56: 1045 | H56: =G56+(D56-F56)*E56 -> 1091.6667
... C142: 14801 | D142: 14900 | E142: 0.038888889 | F142: 5100 | G142: 1045 | H142: =G142+(D142-F142)*E142 -> 1426.1111
B143: - | C143: 14901 | D143: 15000 | E143: 0.038888889 | F143: 5100 | G143: 1045 | H143: =G143+(D143-F143)*E143 -> 1430
B144: - | C144: 15001 | D144: 15100 | E144: 0.025838926 | F144: 15100 | G144: 1455 | H144: =G144+(D144-F144)*E144 -> 1455
C145: 15101 | D145: 15200 | E145: 0.025838926 | F145: 15100 | G145: 1455 | H145: =G145+(D145-F145)*E145 -> 1457.5839
C146: 15201 | D146: 15300 | E146: 0.025838926 | F146: 15100 | G146: 1455 | H146: =G146+(D146-F146)*E146 -> 1460.1678
C147: 15301 | D147: 15400 | E147: 0.025838926 | F147: 15100 | G147: 1455 | H147: =G147+(D147-F147)*E147 -> 1462.7517
C148: 15401 | D148: 15500 | E148: 0.025838926 | F148: 15100 | G148: 1455 | H148: =G148+(D148-F148)*E148 -> 1465.3356
C149: 15501 | D149: 15600 | E149: 0.025838926 | F149: 15100 | G149: 1455 | H149: =G149+(D149-F149)*E149 -> 1467.9195
C150: 15601 | D150: 15700 | E150: 0.025838926 | F150: 15100 | G150: 1455 | H150: =G150+(D150-F150)*E150 -> 1470.5034
C151: 15701 | D151: 15800 | E151: 0.025838926 | F151: 15100 | G151: 1455 | H151: =G151+(D151-F151)*E151 -> 1473.0872
C152: 15801 | D152: 15900 | E152: 0.025838926 | F152: 15100 | G152: 1455 | H152: =G152+(D152-F152)*E152 -> 1475.6711
...

Sheet Pilot
A4: 1.1 თუ გემის პირობითი მოცულობა ნაკლებია 8000 კუბურ მეტრზე, მაშინ გემის პირობითი მოცულობა იანგარიშება როგორც 8000 კუბური მეტრი.

Sheet Mooring

Sheet ANCHORAGE
A1: ჰ62) საქართველოს ნავსადგურში გარე რეიდზე ღუზაზე დგომის დღიური საფასური (მიუხედევად დღე-
A2: ღამის განმავლობაში ღუზაზე დგომის ხანგრძლივობისა):
A3: 500 – 1000 GT – 265 ლარი;
A4: 1001 – 5000 GT – 365 ლარი;
A5: 5001 – 15000 GT – 715 ლარი;
A6: 15001 და < GT – 945 ლარი.
A7: ამ ქვეპუნქტით გათვალისწინებული საფასურის გადახდის ვალდებულება არ ვრცელდება გემებზე,
A8: რომელთა საერთო ტევადობაც არის 500 GT-ზე ნაკლები, დაპატიმრებულ და ადმინისტრაციული წესით
A9: დაკავებულ გემებზე, ასევე ფორსმაჟორული სიტუაციიდან გამომდინარე, ღუზაზე მდგომ ნებისმიერი ტიპის
A10: გემზე. აღნიშნული საფასური შეეხება 500 საერთო ტევადობაზე (GT) მეტ ყველა იმ გემს, რომელიც მოვიდა და
A11: დადგა ნავსადგურის გარე რეიდზე ღუზაზე 24 საათზე მეტი ხნით, იმ პირობით, რომ გემის დანიშნულების
A12: ნავსადგურია საქართველოს ნავსადგური, მაგრამ, ამა თუ იმ მიზეზების გამო ნავსადგურში არ შემოვიდა
... A16: გადაიხდიან ამ ქვეპუნქტში მითითებული საფასურის 20%-ს.

Sheet GEOREP
A1: ძებნა-გადარჩენის სისტემაში მონაწილეობის საფასური, გარდა ამ მუხლის „ჰ64“, „ჰ67“, „ჰ68“, და „ჰ72“
A2: ქვეპუნქტებით განსაზღვრული შემთხვევებისა – 580 ლარი;

Sheet MONITORING
A1: საქართველოს ნავსადგურში ყოველი შესვლა/გასვლის მიზნით საქართველოს ტერიტორიულ ზღვასა
A2: და ნავსადგურის აკვატორიაში გემების მოძრაობის მონიტორინგისა და საინფორმაციო სისტემებით
A3: მომსახურების საფასური 1 GT-ზე ყველა ტიპის გემისთვის, გარდა თევზსაჭერი, თევზსარეწი და თევზის
A4: ნედლეულისა და რეწვის პროდუქციის სატრანსპორტო გემებისა – 0.16 ლარი.
A5: შენიშვნა: სამხედრო გემები, აგრეთვე გემები, რომლებიც საქართველოს ნავსადგურებში შემოდიან
A6: ნავსადგურებისთვის სანავსადგურე ინფრასტრუქტურაზე საჭირო სამუშაოების შესასრულებლად
A7: გათავისუფლდებიან ამ ქვეპუნქტით დადგენილი საფასურის გადახდის ვალდებულებისგან. საერთაშორისო
A8: ხელშეკრულების შესაბამისად დანიშნული სახაზო გემებისთვის ამ ქვეპუნქტით განსაზღვრული საფასურის
A9: განაკვეთი შემცირდება 20%-ით.
A10: თუ გემი ერთი შემოსვლის ფარგლებში შედის საქართველოს რამდენიმე ნავსადგურში, პირველ
A11: ნავსადგურში შესვლის დროს იხდის ამ პუნქტით გათვალისწინებული საფასურის 100%, ხოლო მეორე და
A12: შემდგომ ნავსადგურში შესვლის შემთხვევაში ამ მუხლით გათვალისწინებული საფასური მცირდება 50%-ით.
A13: (ამოქმედდეს 2023 წლის 1 იანვრიდან)].
